[2023-01-08T16:33:35.613+0000] {taskinstance.py:1087} INFO - Dependencies all met for <TaskInstance: UK_Accidents_2020-DAG.Load_to_postgres manual__2023-01-08T16:32:39.072222+00:00 [queued]>
[2023-01-08T16:33:35.635+0000] {taskinstance.py:1087} INFO - Dependencies all met for <TaskInstance: UK_Accidents_2020-DAG.Load_to_postgres manual__2023-01-08T16:32:39.072222+00:00 [queued]>
[2023-01-08T16:33:35.635+0000] {taskinstance.py:1283} INFO - 
--------------------------------------------------------------------------------
[2023-01-08T16:33:35.635+0000] {taskinstance.py:1284} INFO - Starting attempt 1 of 1
[2023-01-08T16:33:35.635+0000] {taskinstance.py:1285} INFO - 
--------------------------------------------------------------------------------
[2023-01-08T16:33:35.673+0000] {taskinstance.py:1304} INFO - Executing <Task(PythonOperator): Load_to_postgres> on 2023-01-08 16:32:39.072222+00:00
[2023-01-08T16:33:35.693+0000] {standard_task_runner.py:55} INFO - Started process 2418 to run task
[2023-01-08T16:33:35.707+0000] {standard_task_runner.py:82} INFO - Running: ['***', 'tasks', 'run', 'UK_Accidents_2020-DAG', 'Load_to_postgres', 'manual__2023-01-08T16:32:39.072222+00:00', '--job-id', '180', '--raw', '--subdir', 'DAGS_FOLDER/flow.py', '--cfg-path', '/tmp/tmp4fnrj331']
[2023-01-08T16:33:35.713+0000] {standard_task_runner.py:83} INFO - Job 180: Subtask Load_to_postgres
[2023-01-08T16:33:36.019+0000] {task_command.py:389} INFO - Running <TaskInstance: UK_Accidents_2020-DAG.Load_to_postgres manual__2023-01-08T16:32:39.072222+00:00 [running]> on host 4772e9b170d7
[2023-01-08T16:33:36.176+0000] {taskinstance.py:1513} INFO - Exporting the following env vars:
AIRFLOW_CTX_DAG_OWNER=***
AIRFLOW_CTX_DAG_ID=UK_Accidents_2020-DAG
AIRFLOW_CTX_TASK_ID=Load_to_postgres
AIRFLOW_CTX_EXECUTION_DATE=2023-01-08T16:32:39.072222+00:00
AIRFLOW_CTX_TRY_NUMBER=1
AIRFLOW_CTX_DAG_RUN_ID=manual__2023-01-08T16:32:39.072222+00:00
[2023-01-08T16:33:37.862+0000] {logging_mixin.py:137} WARNING - /opt/***/dags/flow.py:26 DtypeWarning: Columns (0,2,20) have mixed types.Specify dtype option on import or set low_memory=False.
[2023-01-08T16:33:40.410+0000] {logging_mixin.py:137} WARNING - /opt/***/dags/flow.py:26 DtypeWarning: Columns (1,3,21) have mixed types.Specify dtype option on import or set low_memory=False.
[2023-01-08T16:33:40.458+0000] {logging_mixin.py:137} INFO - Engine(postgresql://root:***@pgdatabase:5432/milestone2_etl)
[2023-01-08T16:33:50.717+0000] {taskinstance.py:1772} ERROR - Task failed with exception
Traceback (most recent call last):
  File "/home/airflow/.local/lib/python3.7/site-packages/sqlalchemy/engine/base.py", line 3361, in _wrap_pool_connect
    return fn()
  File "/home/airflow/.local/lib/python3.7/site-packages/sqlalchemy/pool/base.py", line 325, in connect
    return _ConnectionFairy._checkout(self)
  File "/home/airflow/.local/lib/python3.7/site-packages/sqlalchemy/pool/base.py", line 888, in _checkout
    fairy = _ConnectionRecord.checkout(pool)
  File "/home/airflow/.local/lib/python3.7/site-packages/sqlalchemy/pool/base.py", line 491, in checkout
    rec = pool._do_get()
  File "/home/airflow/.local/lib/python3.7/site-packages/sqlalchemy/pool/impl.py", line 146, in _do_get
    self._dec_overflow()
  File "/home/airflow/.local/lib/python3.7/site-packages/sqlalchemy/util/langhelpers.py", line 72, in __exit__
    with_traceback=exc_tb,
  File "/home/airflow/.local/lib/python3.7/site-packages/sqlalchemy/util/compat.py", line 210, in raise_
    raise exception
  File "/home/airflow/.local/lib/python3.7/site-packages/sqlalchemy/pool/impl.py", line 143, in _do_get
    return self._create_connection()
  File "/home/airflow/.local/lib/python3.7/site-packages/sqlalchemy/pool/base.py", line 271, in _create_connection
    return _ConnectionRecord(self)
  File "/home/airflow/.local/lib/python3.7/site-packages/sqlalchemy/pool/base.py", line 386, in __init__
    self.__connect()
  File "/home/airflow/.local/lib/python3.7/site-packages/sqlalchemy/pool/base.py", line 685, in __connect
    pool.logger.debug("Error on connect(): %s", e)
  File "/home/airflow/.local/lib/python3.7/site-packages/sqlalchemy/util/langhelpers.py", line 72, in __exit__
    with_traceback=exc_tb,
  File "/home/airflow/.local/lib/python3.7/site-packages/sqlalchemy/util/compat.py", line 210, in raise_
    raise exception
  File "/home/airflow/.local/lib/python3.7/site-packages/sqlalchemy/pool/base.py", line 680, in __connect
    self.dbapi_connection = connection = pool._invoke_creator(self)
  File "/home/airflow/.local/lib/python3.7/site-packages/sqlalchemy/engine/create.py", line 578, in connect
    return dialect.connect(*cargs, **cparams)
  File "/home/airflow/.local/lib/python3.7/site-packages/sqlalchemy/engine/default.py", line 598, in connect
    return self.dbapi.connect(*cargs, **cparams)
  File "/home/airflow/.local/lib/python3.7/site-packages/psycopg2/__init__.py", line 122, in connect
    conn = _connect(dsn, connection_factory=connection_factory, **kwasync)
psycopg2.OperationalError: could not translate host name "pgdatabase" to address: Temporary failure in name resolution


The above exception was the direct cause of the following exception:

Traceback (most recent call last):
  File "/home/airflow/.local/lib/python3.7/site-packages/airflow/operators/python.py", line 175, in execute
    return_value = self.execute_callable()
  File "/home/airflow/.local/lib/python3.7/site-packages/airflow/operators/python.py", line 192, in execute_callable
    return self.python_callable(*self.op_args, **self.op_kwargs)
  File "/opt/airflow/dags/flow.py", line 26, in task2_postgres
    tables_to_postgres()
  File "/opt/airflow/dags/postgres/postgres.py", line 14, in tables_to_postgres
    df.to_sql('UK_Accidents_2020', con = conn, if_exists = 'replace', index = False)
  File "/home/airflow/.local/lib/python3.7/site-packages/pandas/core/generic.py", line 2882, in to_sql
    method=method,
  File "/home/airflow/.local/lib/python3.7/site-packages/pandas/io/sql.py", line 728, in to_sql
    **engine_kwargs,
  File "/home/airflow/.local/lib/python3.7/site-packages/pandas/io/sql.py", line 1758, in to_sql
    dtype=dtype,
  File "/home/airflow/.local/lib/python3.7/site-packages/pandas/io/sql.py", line 1650, in prep_table
    table.create()
  File "/home/airflow/.local/lib/python3.7/site-packages/pandas/io/sql.py", line 856, in create
    if self.exists():
  File "/home/airflow/.local/lib/python3.7/site-packages/pandas/io/sql.py", line 840, in exists
    return self.pd_sql.has_table(self.name, self.schema)
  File "/home/airflow/.local/lib/python3.7/site-packages/pandas/io/sql.py", line 1783, in has_table
    insp = sa.inspect(self.connectable)
  File "/home/airflow/.local/lib/python3.7/site-packages/sqlalchemy/inspection.py", line 64, in inspect
    ret = reg(subject)
  File "/home/airflow/.local/lib/python3.7/site-packages/sqlalchemy/engine/reflection.py", line 182, in _engine_insp
    return Inspector._construct(Inspector._init_engine, bind)
  File "/home/airflow/.local/lib/python3.7/site-packages/sqlalchemy/engine/reflection.py", line 117, in _construct
    init(self, bind)
  File "/home/airflow/.local/lib/python3.7/site-packages/sqlalchemy/engine/reflection.py", line 128, in _init_engine
    engine.connect().close()
  File "/home/airflow/.local/lib/python3.7/site-packages/sqlalchemy/engine/base.py", line 3315, in connect
    return self._connection_cls(self, close_with_result=close_with_result)
  File "/home/airflow/.local/lib/python3.7/site-packages/sqlalchemy/engine/base.py", line 96, in __init__
    else engine.raw_connection()
  File "/home/airflow/.local/lib/python3.7/site-packages/sqlalchemy/engine/base.py", line 3394, in raw_connection
    return self._wrap_pool_connect(self.pool.connect, _connection)
  File "/home/airflow/.local/lib/python3.7/site-packages/sqlalchemy/engine/base.py", line 3365, in _wrap_pool_connect
    e, dialect, self
  File "/home/airflow/.local/lib/python3.7/site-packages/sqlalchemy/engine/base.py", line 2199, in _handle_dbapi_exception_noconnection
    sqlalchemy_exception, with_traceback=exc_info[2], from_=e
  File "/home/airflow/.local/lib/python3.7/site-packages/sqlalchemy/util/compat.py", line 210, in raise_
    raise exception
  File "/home/airflow/.local/lib/python3.7/site-packages/sqlalchemy/engine/base.py", line 3361, in _wrap_pool_connect
    return fn()
  File "/home/airflow/.local/lib/python3.7/site-packages/sqlalchemy/pool/base.py", line 325, in connect
    return _ConnectionFairy._checkout(self)
  File "/home/airflow/.local/lib/python3.7/site-packages/sqlalchemy/pool/base.py", line 888, in _checkout
    fairy = _ConnectionRecord.checkout(pool)
  File "/home/airflow/.local/lib/python3.7/site-packages/sqlalchemy/pool/base.py", line 491, in checkout
    rec = pool._do_get()
  File "/home/airflow/.local/lib/python3.7/site-packages/sqlalchemy/pool/impl.py", line 146, in _do_get
    self._dec_overflow()
  File "/home/airflow/.local/lib/python3.7/site-packages/sqlalchemy/util/langhelpers.py", line 72, in __exit__
    with_traceback=exc_tb,
  File "/home/airflow/.local/lib/python3.7/site-packages/sqlalchemy/util/compat.py", line 210, in raise_
    raise exception
  File "/home/airflow/.local/lib/python3.7/site-packages/sqlalchemy/pool/impl.py", line 143, in _do_get
    return self._create_connection()
  File "/home/airflow/.local/lib/python3.7/site-packages/sqlalchemy/pool/base.py", line 271, in _create_connection
    return _ConnectionRecord(self)
  File "/home/airflow/.local/lib/python3.7/site-packages/sqlalchemy/pool/base.py", line 386, in __init__
    self.__connect()
  File "/home/airflow/.local/lib/python3.7/site-packages/sqlalchemy/pool/base.py", line 685, in __connect
    pool.logger.debug("Error on connect(): %s", e)
  File "/home/airflow/.local/lib/python3.7/site-packages/sqlalchemy/util/langhelpers.py", line 72, in __exit__
    with_traceback=exc_tb,
  File "/home/airflow/.local/lib/python3.7/site-packages/sqlalchemy/util/compat.py", line 210, in raise_
    raise exception
  File "/home/airflow/.local/lib/python3.7/site-packages/sqlalchemy/pool/base.py", line 680, in __connect
    self.dbapi_connection = connection = pool._invoke_creator(self)
  File "/home/airflow/.local/lib/python3.7/site-packages/sqlalchemy/engine/create.py", line 578, in connect
    return dialect.connect(*cargs, **cparams)
  File "/home/airflow/.local/lib/python3.7/site-packages/sqlalchemy/engine/default.py", line 598, in connect
    return self.dbapi.connect(*cargs, **cparams)
  File "/home/airflow/.local/lib/python3.7/site-packages/psycopg2/__init__.py", line 122, in connect
    conn = _connect(dsn, connection_factory=connection_factory, **kwasync)
sqlalchemy.exc.OperationalError: (psycopg2.OperationalError) could not translate host name "pgdatabase" to address: Temporary failure in name resolution

(Background on this error at: https://sqlalche.me/e/14/e3q8)
[2023-01-08T16:33:50.758+0000] {taskinstance.py:1327} INFO - Marking task as FAILED. dag_id=UK_Accidents_2020-DAG, task_id=Load_to_postgres, execution_date=20230108T163239, start_date=20230108T163335, end_date=20230108T163350
[2023-01-08T16:33:50.814+0000] {standard_task_runner.py:105} ERROR - Failed to execute job 180 for task Load_to_postgres ((psycopg2.OperationalError) could not translate host name "pgdatabase" to address: Temporary failure in name resolution

(Background on this error at: https://sqlalche.me/e/14/e3q8); 2418)
[2023-01-08T16:33:50.921+0000] {local_task_job.py:159} INFO - Task exited with return code 1
[2023-01-08T16:33:50.997+0000] {taskinstance.py:2582} INFO - 0 downstream tasks scheduled from follow-on schedule check
