[2023-01-08T13:38:18.225+0000] {taskinstance.py:1087} INFO - Dependencies all met for <TaskInstance: UK_Accidents_2020-DAG.extract_clean_data manual__2023-01-08T13:38:15.913984+00:00 [queued]>
[2023-01-08T13:38:18.244+0000] {taskinstance.py:1087} INFO - Dependencies all met for <TaskInstance: UK_Accidents_2020-DAG.extract_clean_data manual__2023-01-08T13:38:15.913984+00:00 [queued]>
[2023-01-08T13:38:18.244+0000] {taskinstance.py:1283} INFO - 
--------------------------------------------------------------------------------
[2023-01-08T13:38:18.245+0000] {taskinstance.py:1284} INFO - Starting attempt 1 of 1
[2023-01-08T13:38:18.245+0000] {taskinstance.py:1285} INFO - 
--------------------------------------------------------------------------------
[2023-01-08T13:38:18.341+0000] {taskinstance.py:1304} INFO - Executing <Task(PythonOperator): extract_clean_data> on 2023-01-08 13:38:15.913984+00:00
[2023-01-08T13:38:18.353+0000] {standard_task_runner.py:55} INFO - Started process 1147 to run task
[2023-01-08T13:38:18.404+0000] {standard_task_runner.py:82} INFO - Running: ['***', 'tasks', 'run', 'UK_Accidents_2020-DAG', 'extract_clean_data', 'manual__2023-01-08T13:38:15.913984+00:00', '--job-id', '74', '--raw', '--subdir', 'DAGS_FOLDER/flow.py', '--cfg-path', '/tmp/tmpyddxln6a']
[2023-01-08T13:38:18.428+0000] {standard_task_runner.py:83} INFO - Job 74: Subtask extract_clean_data
[2023-01-08T13:38:18.709+0000] {task_command.py:389} INFO - Running <TaskInstance: UK_Accidents_2020-DAG.extract_clean_data manual__2023-01-08T13:38:15.913984+00:00 [running]> on host 07df51a91e47
[2023-01-08T13:38:19.137+0000] {taskinstance.py:1513} INFO - Exporting the following env vars:
AIRFLOW_CTX_DAG_OWNER=***
AIRFLOW_CTX_DAG_ID=UK_Accidents_2020-DAG
AIRFLOW_CTX_TASK_ID=extract_clean_data
AIRFLOW_CTX_EXECUTION_DATE=2023-01-08T13:38:15.913984+00:00
AIRFLOW_CTX_TRY_NUMBER=1
AIRFLOW_CTX_DAG_RUN_ID=manual__2023-01-08T13:38:15.913984+00:00
[2023-01-08T13:38:19.148+0000] {taskinstance.py:1772} ERROR - Task failed with exception
Traceback (most recent call last):
  File "/home/airflow/.local/lib/python3.7/site-packages/airflow/operators/python.py", line 175, in execute
    return_value = self.execute_callable()
  File "/home/airflow/.local/lib/python3.7/site-packages/airflow/operators/python.py", line 192, in execute_callable
    return self.python_callable(*self.op_args, **self.op_kwargs)
  File "/opt/airflow/dags/flow.py", line 19, in task1_ETL
    df = pd.read_csv(path_to_csv)
  File "/home/airflow/.local/lib/python3.7/site-packages/pandas/util/_decorators.py", line 311, in wrapper
    return func(*args, **kwargs)
  File "/home/airflow/.local/lib/python3.7/site-packages/pandas/io/parsers/readers.py", line 586, in read_csv
    return _read(filepath_or_buffer, kwds)
  File "/home/airflow/.local/lib/python3.7/site-packages/pandas/io/parsers/readers.py", line 482, in _read
    parser = TextFileReader(filepath_or_buffer, **kwds)
  File "/home/airflow/.local/lib/python3.7/site-packages/pandas/io/parsers/readers.py", line 811, in __init__
    self._engine = self._make_engine(self.engine)
  File "/home/airflow/.local/lib/python3.7/site-packages/pandas/io/parsers/readers.py", line 1040, in _make_engine
    return mapping[engine](self.f, **self.options)  # type: ignore[call-arg]
  File "/home/airflow/.local/lib/python3.7/site-packages/pandas/io/parsers/c_parser_wrapper.py", line 51, in __init__
    self._open_handles(src, kwds)
  File "/home/airflow/.local/lib/python3.7/site-packages/pandas/io/parsers/base_parser.py", line 229, in _open_handles
    errors=kwds.get("encoding_errors", "strict"),
  File "/home/airflow/.local/lib/python3.7/site-packages/pandas/io/common.py", line 707, in get_handle
    newline="",
FileNotFoundError: [Errno 2] No such file or directory: '2020_Accidents_UK.csv'
[2023-01-08T13:38:19.222+0000] {taskinstance.py:1327} INFO - Marking task as FAILED. dag_id=UK_Accidents_2020-DAG, task_id=extract_clean_data, execution_date=20230108T133815, start_date=20230108T133818, end_date=20230108T133819
[2023-01-08T13:38:19.296+0000] {standard_task_runner.py:105} ERROR - Failed to execute job 74 for task extract_clean_data ([Errno 2] No such file or directory: '2020_Accidents_UK.csv'; 1147)
[2023-01-08T13:38:19.329+0000] {local_task_job.py:159} INFO - Task exited with return code 1
[2023-01-08T13:38:19.553+0000] {taskinstance.py:2582} INFO - 0 downstream tasks scheduled from follow-on schedule check
