[2023-01-08T14:04:06.819+0000] {taskinstance.py:1087} INFO - Dependencies all met for <TaskInstance: UK_Accidents_2020-DAG.Load_to_postgres manual__2023-01-08T14:03:07.966792+00:00 [queued]>
[2023-01-08T14:04:06.837+0000] {taskinstance.py:1087} INFO - Dependencies all met for <TaskInstance: UK_Accidents_2020-DAG.Load_to_postgres manual__2023-01-08T14:03:07.966792+00:00 [queued]>
[2023-01-08T14:04:06.838+0000] {taskinstance.py:1283} INFO - 
--------------------------------------------------------------------------------
[2023-01-08T14:04:06.838+0000] {taskinstance.py:1284} INFO - Starting attempt 1 of 1
[2023-01-08T14:04:06.838+0000] {taskinstance.py:1285} INFO - 
--------------------------------------------------------------------------------
[2023-01-08T14:04:06.870+0000] {taskinstance.py:1304} INFO - Executing <Task(PythonOperator): Load_to_postgres> on 2023-01-08 14:03:07.966792+00:00
[2023-01-08T14:04:06.879+0000] {standard_task_runner.py:55} INFO - Started process 1319 to run task
[2023-01-08T14:04:06.886+0000] {standard_task_runner.py:82} INFO - Running: ['***', 'tasks', 'run', 'UK_Accidents_2020-DAG', 'Load_to_postgres', 'manual__2023-01-08T14:03:07.966792+00:00', '--job-id', '112', '--raw', '--subdir', 'DAGS_FOLDER/flow.py', '--cfg-path', '/tmp/tmppfv1fe1b']
[2023-01-08T14:04:06.889+0000] {standard_task_runner.py:83} INFO - Job 112: Subtask Load_to_postgres
[2023-01-08T14:04:07.018+0000] {task_command.py:389} INFO - Running <TaskInstance: UK_Accidents_2020-DAG.Load_to_postgres manual__2023-01-08T14:03:07.966792+00:00 [running]> on host 07df51a91e47
[2023-01-08T14:04:07.174+0000] {taskinstance.py:1513} INFO - Exporting the following env vars:
AIRFLOW_CTX_DAG_OWNER=***
AIRFLOW_CTX_DAG_ID=UK_Accidents_2020-DAG
AIRFLOW_CTX_TASK_ID=Load_to_postgres
AIRFLOW_CTX_EXECUTION_DATE=2023-01-08T14:03:07.966792+00:00
AIRFLOW_CTX_TRY_NUMBER=1
AIRFLOW_CTX_DAG_RUN_ID=manual__2023-01-08T14:03:07.966792+00:00
[2023-01-08T14:04:07.180+0000] {taskinstance.py:1772} ERROR - Task failed with exception
Traceback (most recent call last):
  File "/home/airflow/.local/lib/python3.7/site-packages/airflow/operators/python.py", line 175, in execute
    return_value = self.execute_callable()
  File "/home/airflow/.local/lib/python3.7/site-packages/airflow/operators/python.py", line 192, in execute_callable
    return self.python_callable(*self.op_args, **self.op_kwargs)
  File "/opt/airflow/dags/flow.py", line 26, in task2_postgres
    tables_to_postgres()
  File "/opt/airflow/dags/postgres/postgres.py", line 9, in tables_to_postgres
    df = pd.read_csv(path_to_table)
  File "/home/airflow/.local/lib/python3.7/site-packages/pandas/util/_decorators.py", line 311, in wrapper
    return func(*args, **kwargs)
  File "/home/airflow/.local/lib/python3.7/site-packages/pandas/io/parsers/readers.py", line 586, in read_csv
    return _read(filepath_or_buffer, kwds)
  File "/home/airflow/.local/lib/python3.7/site-packages/pandas/io/parsers/readers.py", line 482, in _read
    parser = TextFileReader(filepath_or_buffer, **kwds)
  File "/home/airflow/.local/lib/python3.7/site-packages/pandas/io/parsers/readers.py", line 811, in __init__
    self._engine = self._make_engine(self.engine)
  File "/home/airflow/.local/lib/python3.7/site-packages/pandas/io/parsers/readers.py", line 1040, in _make_engine
    return mapping[engine](self.f, **self.options)  # type: ignore[call-arg]
  File "/home/airflow/.local/lib/python3.7/site-packages/pandas/io/parsers/c_parser_wrapper.py", line 51, in __init__
    self._open_handles(src, kwds)
  File "/home/airflow/.local/lib/python3.7/site-packages/pandas/io/parsers/base_parser.py", line 229, in _open_handles
    errors=kwds.get("encoding_errors", "strict"),
  File "/home/airflow/.local/lib/python3.7/site-packages/pandas/io/common.py", line 707, in get_handle
    newline="",
FileNotFoundError: [Errno 2] No such file or directory: '/opt/airflow/DAG/2020_Accidents_UK.csv'
[2023-01-08T14:04:07.201+0000] {taskinstance.py:1327} INFO - Marking task as FAILED. dag_id=UK_Accidents_2020-DAG, task_id=Load_to_postgres, execution_date=20230108T140307, start_date=20230108T140406, end_date=20230108T140407
[2023-01-08T14:04:07.233+0000] {standard_task_runner.py:105} ERROR - Failed to execute job 112 for task Load_to_postgres ([Errno 2] No such file or directory: '/opt/airflow/DAG/2020_Accidents_UK.csv'; 1319)
[2023-01-08T14:04:07.257+0000] {local_task_job.py:159} INFO - Task exited with return code 1
[2023-01-08T14:04:07.307+0000] {taskinstance.py:2582} INFO - 0 downstream tasks scheduled from follow-on schedule check
